
exception Return 

let f = fun () ->
  {  }
  let j = 42 in
  void
  { true }

let g = fun () ->
  {  }
  let return = 0 in
  try
    let j = 42 in 
    let return = j in 
    raise Return
  with Return ->
    return end
  { result >= 0 }
